File: Traction/0_1.txt
File Path: C:\MTS TestSuite\Data Files\Olivier C\0_1_2 01-22-21 10 59 25 AM\DAQ- Time, … - (Timed).txt
Test: MTS EM Tension (Extensometer) 3
Test Run: 0_1_2
Date: 1/22/2021 10:57:40 AM


Time 	Load 	Crosshead 	Extensometer 	Strain 	Stress
sec	N	mm	mm	mm/mm	N/mm²
0.109999999403954	57.2181510925293	0.00300009219245112	0.000120419116456105	1.17033314381843E-05	3.69279675
0.310000002384186	65.2815780639648	0.00969260599958943	0.00263194988292526	4.77162793686148E-05	4.2132015
0.509999990463257	73.6774978637695	0.0161543430294842	0.00512496080773417	8.73622848303057E-05	4.755065
0.709999978542328	82.18017578125	0.0228468579734908	0.00596325662627351	0.00011353367153788	5.3038185
0.910000026226044	90.2451934814453	0.0295393710985081	0.00743327791496995	0.000164126846357249	5.824326
1.11000001430511	98.2973403930664	0.036231882404536	0.00963589172897628	0.000193112762644887	6.3440025
1.30999994277954	107.277603149414	0.0429243955295533	0.0120439381134929	0.000229422745178454	6.923579
1.50999999046326	114.848258972168	0.0496169122925494	0.0130646158140735	0.000259214022662491	7.412181
1.71000003814697	123.85986328125	0.0563094254175667	0.0152420479935245	0.000285222864476964	7.99378
1.9099999666214	132.39860534668	0.0630019349046052	0.0166276786330855	0.000337435223627836	8.544861
2.10999989509583	140.239669799805	0.0696944553055801	0.0182718013093108	0.000377831922378391	9.050915
2.30999994277954	148.77131652832	0.0761561896069907	0.020132414647378	0.000395456241676584	9.601538
2.50999999046326	157.030227661133	0.0830794815556146	0.0219933481275802	0.000426173181040213	10.134559
2.71000003814697	165.118118286133	0.0895412158570252	0.0238861503021326	0.000470503699034452	10.656543
2.91000008583069	174.109283447266	0.0962337362580001	0.0249942004302284	0.000504055584315211	11.236823
3.10999989509583	182.289398193359	0.102926249383017	0.027173204216524	0.000530276040080935	11.764758
3.30999994277954	190.174499511719	0.109618762508035	0.0288547380478121	0.000565963855478913	12.273654
3.50999999046326	199.072280883789	0.116311275633052	0.0302306216326542	0.000593016913626343	12.847907
3.71000003814697	207.251571655273	0.123003788758069	0.0318422098644078	0.000636814860627055	13.375789
3.91000008583069	215.223281860352	0.12946552305948	0.0335674012603704	0.000653171387966722	13.890275
4.1100001335144	223.937164306641	0.136158036184497	0.0359529985871632	0.000706288905348629	14.452659
4.30999994277954	232.401519775391	0.142850549309514	0.0374765550077427	0.000735391455236822	14.99894
4.51000022888184	241.240982055664	0.149543062434532	0.0383865663025063	0.0007570197340101	15.569429
4.71000003814697	248.963317871094	0.156235575559549	0.0408256018999964	0.000802088412456214	16.06782
4.90999984741211	258.103271484375	0.162928088684566	0.041901945223799	0.000833639234770089	16.657703
5.1100001335144	265.690856933594	0.169389822985977	0.0443036587967072	0.000868587230797857	17.147396
5.30999994277954	274.182403564453	0.176082336110994	0.0457131354778539	0.000909606053028256	17.695432
5.51000022888184	282.075653076172	0.182774863787927	0.0468512080260552	0.000924418505746871	18.204854
5.71000003814697	290.603942871094	0.189467376912944	0.049196485633729	0.000967482395935804	18.75526
5.90999984741211	298.631225585938	0.196159890037961	0.0500562127854209	0.000991701264865696	19.273332
6.1100001335144	307.075653076172	0.202621624339372	0.0526951153005939	0.0010300048161298	19.818326
6.30999994277954	314.545928955078	0.209544916287996	0.0541395529580768	0.00107281003147364	20.30045
6.51000022888184	323.506744384766	0.216237429413013	0.0557207749807276	0.00109543860889971	20.878772
6.71000003814697	331.519989013672	0.22292994253803	0.0574213991058059	0.00113216310273856	21.395938
6.90999984741211	339.32568359375	0.229391676839441	0.0596066056459676	0.00116429117042571	21.899708
7.1100001335144	347.549591064453	0.236314968788065	0.0607605616096407	0.00119546742644161	22.43047
7.30999994277954	355.815460205078	0.243007481913082	0.0620810023974627	0.00123801722656935	22.96394
7.51000022888184	363.288665771484	0.249699980486184	0.0638061028439552	0.001258505275473	23.446252
7.71000003814697	371.366912841797	0.25616172933951	0.0653231836622581	0.00129102321807295	23.967614
7.90999984741211	379.200653076172	0.262854242464527	0.0673324975650758	0.00131763657554984	24.473194
8.10999965667725	387.241577148438	0.269546755589545	0.0694214832037687	0.00135299994144589	24.992148
8.3100004196167	395.330352783203	0.276239268714562	0.0705500060576014	0.00138840056024492	25.514188
8.51000022888184	402.845550537109	0.282931781839579	0.0725810386938974	0.00142575043719262	25.99921
8.71000003814697	410.529571533203	0.289624294964597	0.0737687441869639	0.00145215843804181	26.49513
8.90999984741211	418.704711914063	0.296316808089614	0.0763989228289574	0.00148790853563696	27.022744
9.10999965667725	426.173187255859	0.303009321214631	0.0772059502196498	0.00152192753739655	27.50475
9.3100004196167	434.193603515625	0.309701834339648	0.0792233040556312	0.00154450605623424	28.02238
9.51000022888184	441.954193115234	0.316394347464666	0.0805854942882434	0.00159214611630887	28.52324
9.71000003814697	449.182769775391	0.323086860589683	0.0825790921226144	0.00162794697098434	28.989764
9.90999984741211	456.944549560547	0.3297793737147	0.0839333370095119	0.00165766710415483	29.4907
10.1099996566772	464.74072265625	0.336471886839718	0.0865482943481766	0.00169471895787865	29.993858
10.3100004196167	472.464294433594	0.342933635693043	0.0872651216923259	0.00173928227741271	30.492328
10.5100002288818	480.120330810547	0.349626148818061	0.0892896059667692	0.0017684466438368	30.98644
10.710000038147	487.118530273438	0.356318661943078	0.091833011538256	0.00179074367042631	31.438096
10.9099998474121	495.203430175781	0.363011175068095	0.0922126710065641	0.00182418653275818	31.959888
11.1099996566772	502.487823486328	0.369703688193113	0.0944048078963533	0.00185352715197951	32.430014
11.3100004196167	509.826782226563	0.376165407942608	0.0959874741965905	0.00188914930913597	32.903662
11.5100002288818	517.332641601563	0.382857950171456	0.0977518575382419	0.00192299613263458	33.388082
11.710000038147	525.236389160156	0.389550434192643	0.0996217713691294	0.00195192580576986	33.89818
11.9099998474121	532.087646484375	0.39624297642149	0.100433382613119	0.00198277202434838	34.340356
12.1099996566772	539.7802734375	0.402935489546508	0.103197337011807	0.00201419973745942	34.836828
12.3100004196167	547.125183105469	0.409397209296003	0.104835628008004	0.00204897439107299	35.31086
12.5100002288818	554.396606445313	0.41608972242102	0.106036859506276	0.0020932094193995	35.780148
12.710000038147	561.707458496094	0.422782235546038	0.107629224658012	0.00211345590651035	36.251984
12.9099998474121	569.309997558594	0.429474748671055	0.108755622932222	0.00214576628059149	36.742644
13.1099996566772	576.24853515625	0.43593646842055	0.111269204353448	0.00217772857286036	37.190448
13.3100004196167	583.608764648438	0.442629010649398	0.112587411422282	0.00221264688298106	37.665472
13.5100002288818	590.772216796875	0.449321494670585	0.11443344556028	0.00224811094813049	38.127792
13.710000038147	598.226135253906	0.456014036899433	0.11577097029658	0.00227260030806065	38.60886
13.9099998474121	605.672302246094	0.46270655002445	0.117767085612286	0.00232157949358225	39.089428
14.1099996566772	612.365661621094	0.469399063149467	0.119676566100679	0.00234536128118634	39.521408
14.3100004196167	619.377197265625	0.476091576274484	0.120800279546529	0.00237283878959715	39.973928
14.5100002288818	626.477905273438	0.482784089399502	0.121824145026039	0.00241222837939858	40.4322
14.710000038147	633.974670410156	0.489476602524519	0.123954334412701	0.00244183791801333	40.916032
14.9099998474121	641.164794921875	0.496169144753367	0.126118000480346	0.00247156783007085	41.380072
15.1099996566772	648.37646484375	0.502630835399032	0.127672814414836	0.00252046692185104	41.845508
15.3100004196167	655.489379882813	0.509323377627879	0.129046806250699	0.0025406654458493	42.304568
15.5100002288818	662.641540527344	0.516015861649066	0.131136344862171	0.00257601030170918	42.76616
15.710000038147	669.512573242188	0.522708403877914	0.132938774186186	0.00261048786342144	43.209608
15.9099998474121	676.486572265625	0.529400887899101	0.135283495183103	0.00264278938993812	43.659704
16.1100006103516	683.834289550781	0.536093430127949	0.136276663397439	0.00267794029787183	44.133916
16.3099994659424	690.327575683594	0.542785914149135	0.137474853545427	0.00270831515081227	44.552984
16.5100002288818	697.590637207031	0.549247663002461	0.138813178637065	0.00274403602816164	45.021736
16.7099990844727	705.239562988281	0.555940205231309	0.140919262776151	0.00277235731482506	45.515388
16.9099998474121	712.044311523438	0.562632689252496	0.142710123327561	0.00280968309380114	45.95456
17.1100006103516	719.035339355469	0.569325231481344	0.144640391226858	0.00284428801387548	46.405752
17.3099994659424	726.876220703125	0.57601771550253	0.146487087476999	0.00287531944923103	46.911796
17.5100002288818	733.30126953125	0.582479464355856	0.148338745930232	0.00291826389729977	47.32646
17.7099990844727	740.747680664063	0.589402741752565	0.149754327139817	0.00293926591984928	47.807044
17.9099998474121	746.984497070313	0.595864490605891	0.151424363139085	0.00297886878252029	48.20956
18.1100006103516	753.990478515625	0.602556974627078	0.152708045789041	0.00301345717161894	48.66172
18.3099994659424	760.919372558594	0.609249516855925	0.154499750351533	0.00304210279136896	49.108904
18.5100002288818	767.480041503906	0.615942000877112	0.155859175720252	0.00308073638007045	49.53232
18.7099990844727	774.366760253906	0.62263454310596	0.157890419359319	0.00310840224847198	49.976784
18.9099998474121	781.666198730469	0.629096291959286	0.159444141900167	0.00313981459476054	50.44788
19.1100006103516	788.201965332031	0.635788775980473	0.160926632815972	0.00318251270800829	50.869692
19.3099994659424	795.352355957031	0.64248131820932	0.162915734108537	0.00321845151484013	51.331172
19.5100002288818	801.969604492188	0.649173802230507	0.164442710229196	0.00324340909719467	51.75824
19.7099990844727	808.771789550781	0.655635551083833	0.166253303177655	0.00326520833186805	52.197244
19.9099998474121	816.0498046875	0.662328093312681	0.167732214322314	0.00330346124246717	52.66696
20.1100006103516	822.566589355469	0.669020577333868	0.16944516391959	0.00333386543206871	53.087548
20.3099994659424	829.334655761719	0.675713119562715	0.171033447259106	0.00336964195594192	53.524352
20.5100002288818	836.596130371094	0.682405603583902	0.172779124113731	0.00340798869729042	53.993
20.7099990844727	842.9833984375	0.68909814581275	0.174565546330996	0.00343239936046302	54.405224
20.9099998474121	849.582763671875	0.695559836458415	0.176035799086094	0.00346452347002923	54.83114
21.1100006103516	856.283508300781	0.702252378687263	0.177741196239367	0.00350600876845419	55.2636
21.3099994659424	863.212829589844	0.70894492091611	0.179832626599818	0.0035379861947149	55.710812
21.5100002288818	870.127563476563	0.715637404937297	0.180525777977891	0.00355985364876688	56.15708
21.7099990844727	877.240417480469	0.722329888958484	0.182901596417651	0.00359027739614248	56.616136
21.9099998474121	883.235717773438	0.72879163781181	0.183914744411595	0.0036293005105108	57.003068
22.1100006103516	890.291381835938	0.735484180040658	0.185756725841202	0.00367138627916574	57.458432
22.3099994659424	896.832397460938	0.742176722269505	0.186873599886894	0.0036975434049964	57.88058
22.5100002288818	903.92333984375	0.748869206290692	0.1892823347589	0.00372323673218489	58.338224
22.7099990844727	910.235717773438	0.755561690311879	0.19048759713769	0.00375549262389541	58.745616
22.9099998474121	917.351196289063	0.762254232540727	0.191454528248869	0.00378467701375484	59.20484
23.1100006103516	924.55322265625	0.768946716561913	0.193749583559111	0.00381860928609967	59.669652
23.3099994659424	930.865539550781	0.775639258790761	0.195543398149312	0.00385525450110435	60.077044
23.5100002288818	937.662902832031	0.782331742811948	0.198001420358196	0.00389519263990223	60.515736
23.7099990844727	944.640258789063	0.789024285040796	0.198747409740463	0.00391169171780348	60.966048
23.9099998474121	951.092651367188	0.795716769061983	0.201341856154613	0.00394839514046907	61.38248
24.1100006103516	958.21240234375	0.80240931129083	0.201852497411892	0.00398272508755326	61.84198
24.3099994659424	965.001342773438	0.809101795312017	0.204216252313927	0.00402312818914652	62.280132
24.5100002288818	971.443603515625	0.815794337540865	0.205739415832795	0.004053870216012	62.695908
24.7099990844727	979.26220703125	0.822486821562052	0.207391029107384	0.0040775123052299	63.200512
24.9099998474121	985.583923339844	0.828948570415378	0.209314821404405	0.00412107165902853	63.608508
25.1100006103516	992.411743164063	0.835641112644225	0.210599173442461	0.00415233010426164	64.049168
25.3099994659424	999.599548339844	0.842333596665412	0.212257378734648	0.00418236199766397	64.51306
25.5100002288818	1005.73022460938	0.84902613889426	0.214253886952065	0.00421147560700774	64.908728
25.7099990844727	1012.33587646484	0.855718622915447	0.216223357710987	0.00424933806061745	65.335048
25.9099998474121	1019.98016357422	0.862180371768773	0.217674489249475	0.00427200412377715	65.828404
26.1100006103516	1027.02783203125	0.868872855789959	0.218290413613431	0.00431084400042892	66.283252
26.3099994659424	1033.41845703125	0.875565398018807	0.22064198856242	0.00434274040162563	66.695696
26.5100002288818	1041.05297851563	0.882257940247655	0.222474613110535	0.00438084080815315	67.188416
26.7099990844727	1047.7490234375	0.888950424268842	0.224133502342738	0.00441278610378504	67.620576
26.9099998474121	1054.58581542969	0.895412173122168	0.225324591156095	0.004437948577106	68.061816
27.1100006103516	1061.43090820313	0.902104657143354	0.227765965973958	0.00447553722187877	68.503592
27.3099994659424	1069.06909179688	0.908797199372202	0.228807053645141	0.00450782757252455	68.996552
27.5100002288818	1075.466796875	0.91548974160105	0.230651523452252	0.00454412214457989	69.409448
27.7099990844727	1082.74169921875	0.922182225622237	0.232772741583176	0.00457269139587879	69.87896
27.9099998474121	1089.37573242188	0.928874709643424	0.234113642363809	0.00460636103525758	70.30712
28.1100006103516	1096.3779296875	0.935567251872271	0.235367813729681	0.00463216518983245	70.759032
28.3099994659424	1103.03955078125	0.942029000725597	0.237233281950466	0.00467701116576791	71.188968
28.5100002288818	1110.22326660156	0.948721542954445	0.239353947108611	0.00469717755913734	71.652592
28.7099990844727	1117.58703613281	0.955413968767971	0.241078261751682	0.00473974319174886	72.12784
28.9099998474121	1124.572265625	0.962106510996819	0.241801186348312	0.00476267701014876	72.578664
29.1100006103516	1131.36083984375	0.968799053225666	0.243669215706177	0.00478275772184134	73.016792
29.3099994659424	1138.09301757813	0.975491595454514	0.245580187765881	0.00482569541782141	73.45128
29.5100002288818	1145.78515625	0.982184079475701	0.247130054049194	0.0048664677888155	73.94772
29.7099990844727	1151.64770507813	0.988876563496888	0.248597643803805	0.004892707336694	74.32608
29.9099998474121	1158.65295410156	0.995569163933396	0.25036878651008	0.00491808215156198	74.778192
30.1100006103516	1165.74658203125	1.00226164795458	0.252157129580155	0.00495800049975514	75.236008
30.3099994659424	1172.29724121094	1.00895413197577	0.254106387728825	0.00498040812090039	75.658784
30.5100002288818	1179.08984375	1.01564661599696	0.255907070823014	0.00502346083521843	76.097168
30.7099990844727	1186.05383300781	1.02233910001814	0.257521955063567	0.00506016006693244	76.546616
30.9099998474121	1192.64465332031	1.02903158403933	0.259390333667398	0.0050844238139689	76.971984
31.1100006103516	1199.64489746094	1.03572418447584	0.260461820289493	0.00512991659343243	77.423768
31.3099994659424	1205.95556640625	1.04218593332917	0.262207409832627	0.00515972590073943	77.831048
31.5100002288818	1212.94665527344	1.04887841735035	0.263666384853423	0.00518717430531979	78.282248
31.7099990844727	1220.36181640625	1.05557101778686	0.265530223259702	0.00522553315386176	78.760816
31.9099998474121	1226.4150390625	1.06226350180805	0.266643590293825	0.00525007909163833	79.15148
32.1100006103516	1233.13586425781	1.06895598582923	0.268913252511993	0.00528489332646132	79.58524
32.310001373291	1239.15649414063	1.07564846985042	0.270106422249228	0.00531459553167224	79.9738
32.5099983215332	1246.37573242188	1.08234095387161	0.272069359198213	0.00533859664574265	80.439728
32.7099990844727	1252.76574707031	1.08903343789279	0.273391633527353	0.00538454996421933	80.852128
32.9099998474121	1260.16784667969	1.0957260383293	0.275107508059591	0.00541018228977919	81.329856
33.1100006103516	1265.91577148438	1.10218778718263	0.277250626822934	0.00544923124834895	81.700816
33.310001373291	1272.05102539063	1.10888027120382	0.278162100585178	0.00547012407332659	82.096784
33.5099983215332	1278.58728027344	1.115572755225	0.28007646324113	0.00551220029592514	82.518624
33.7099990844727	1285.53955078125	1.12226535566151	0.281578162685037	0.00552451424300671	82.967312
33.9099998474121	1291.49572753906	1.12872710451484	0.283309782389551	0.00556699046865106	83.35172
34.1100006103516	1297.8994140625	1.13541958853602	0.284543697489426	0.00560173951089382	83.765008
34.310001373291	1305.25390625	1.14211207255721	0.286140275420621	0.0056294109672308	84.239656
34.5099983215332	1311.27807617188	1.1488045565784	0.287672621197999	0.00566456513479352	84.628448
34.7099990844727	1318.44616699219	1.15549704059958	0.289567484287545	0.00569306733086705	85.091072
34.9099998474121	1324.8125	1.16218964103609	0.291243748506531	0.00572560867294669	85.501952
35.1100006103516	1330.64172363281	1.16865138988942	0.293423683615401	0.00576273584738374	85.87816
35.310001373291	1337.36962890625	1.17557460907847	0.293970748316497	0.00580171402543783	86.312368
35.5099983215332	1344.466796875	1.18203635793179	0.296109705232084	0.00582557870075107	86.770416
35.7099990844727	1350.60583496094	1.1887289583683	0.297707476420328	0.00585897034034133	87.166624
35.9099998474121	1356.8408203125	1.19542132597417	0.29980466933921	0.00587792787700891	87.569024
36.1100006103516	1363.48681640625	1.20211380999535	0.300809799227864	0.00591626483947039	87.997944
36.310001373291	1370.56323242188	1.20880641043186	0.30230128322728	0.00595432566478848	88.454648
36.5099983215332	1376.15295410156	1.21526815928519	0.303691311273724	0.0059795742854476	88.815408
36.7099990844727	1382.27697753906	1.22196064330637	0.305876252241433	0.0060222796164453	89.21064
36.9099998474121	1388.95300292969	1.22865324374288	0.307217327645049	0.00604806467890739	89.641504
37.1100006103516	1394.86645507813	1.23557646293193	0.30962930759415	0.00607333797961473	90.023152
37.310001373291	1401.14196777344	1.24203821178526	0.310483243083581	0.00612254347652197	90.428168
37.5099983215332	1407.27355957031	1.24873081222177	0.312028074404225	0.00613216683268547	90.823896
37.7099990844727	1414.69946289063	1.25542317982763	0.313591415761039	0.00617854949086905	91.303152
37.9099998474121	1420.24914550781	1.26211566384882	0.315433135256171	0.0062096850015223	91.661328
38.1100006103516	1426.74914550781	1.26880826428533	0.317376077873632	0.00623762374743819	92.080824
38.310001373291	1432.88110351563	1.27550074830651	0.318689475534484	0.00627554766833782	92.476576
38.5099983215332	1438.76440429688	1.28219334874302	0.320645369356498	0.00630344403907657	92.85628
38.7099990844727	1445.11206054688	1.28888583276421	0.321482337312773	0.00633270479738712	93.265952
38.9099998474121	1451.19018554688	1.2955783167854	0.324070220813155	0.00637071905657649	93.658224
39.1100006103516	1457.06176757813	1.3022709172219	0.325870554661378	0.00639689061790705	94.037168
39.310001373291	1463.26550292969	1.30896328482777	0.327262823702767	0.00643603317439556	94.437552
39.5099983215332	1468.88623046875	1.31565588526428	0.328281166730449	0.00647236173972487	94.800312
39.7099990844727	1474.99658203125	1.32234836928546	0.330269947880879	0.00648958189412951	95.194664
39.9099998474121	1481.13073730469	1.32881011813879	0.331445859046653	0.00651535391807556	95.590552
40.1100006103516	1486.67626953125	1.33550260215998	0.333916075760499	0.00655506970360875	95.948456
40.310001373291	1493.060546875	1.34219520259649	0.335081771481782	0.00658572418615222	96.360496
40.5099983215332	1498.10046386719	1.34888768661767	0.336761790094897	0.00662309676408768	96.68576
40.7099990844727	1503.83203125	1.35558017063886	0.338679645210505	0.00665781646966934	97.055672
40.9099998474121	1509.93920898438	1.36204191949219	0.339709658874199	0.00668122339993715	97.449824
41.1100006103516	1515.6328125	1.36873451992869	0.341774197295308	0.00672398414462805	97.81728
41.310001373291	1521.17834472656	1.37542688753456	0.343231571605429	0.00675149913877249	98.175184
41.5099983215332	1527.23645019531	1.38211937155575	0.344859261531383	0.00678349938243628	98.566168
41.7099990844727	1532.77465820313	1.38881197199225	0.346888584317639	0.00681430194526911	98.9236
41.9099998474121	1538.87182617188	1.39527372084558	0.347986177075654	0.00683570699766278	99.317104
42.1100006103516	1544.13488769531	1.40196620486677	0.349811860360205	0.00687462044879794	99.656776
42.310001373291	1549.36596679688	1.40865868888795	0.352208793628961	0.00690742488950491	99.994384
42.5099983215332	1554.99157714844	1.41535128932446	0.353369076037779	0.00694020930677652	100.357456
42.7099990844727	1560.59753417969	1.42204377334565	0.354483723640442	0.00697870878502727	100.719256
42.9099998474121	1566.04699707031	1.42850552219898	0.35637739347294	0.00700203841552138	101.07096
43.1100006103516	1571.78735351563	1.43542874138802	0.35795709118247	0.00702910171821713	101.441432
43.310001373291	1576.6611328125	1.44189049024135	0.359670724719763	0.0070620127953589	101.755984
43.5099983215332	1582.49438476563	1.44881382584572	0.360726902727038	0.00709575042128563	102.132456
43.7099990844727	1588.29309082031	1.45527557469904	0.362427352229133	0.00713049154728651	102.506696
43.9099998474121	1593.86120605469	1.46196805872023	0.365202053217217	0.00716577190905809	102.866056
44.1100006103516	1598.92236328125	1.46866054274142	0.365844112820923	0.00719099398702383	103.192696
44.310001373291	1604.43054199219	1.47535314317793	0.367681350326166	0.00723342318087816	103.548192
44.5099983215332	1610.02233886719	1.48204562719911	0.369207613402978	0.00726329488679767	103.90908
44.7099990844727	1615.07604980469	1.4887381112203	0.370577705325559	0.00729050952941179	104.23524
44.9099998474121	1620.77429199219	1.49543059524149	0.37225685082376	0.00732485810294747	104.603
45.1100006103516	1625.82897949219	1.50212307926267	0.373298476915807	0.00736330356448889	104.929224
45.310001373291	1631.71484375	1.50881567969918	0.375704577891156	0.00738087762147188	105.309088
45.5099983215332	1636.98388671875	1.51550816372037	0.376347394194454	0.00741306087002158	105.649144
45.7099990844727	1642.7392578125	1.52220064774156	0.378851866116747	0.00744661595672369	106.020592
45.9099998474121	1648.09594726563	1.52866239659488	0.380096636945382	0.00749354157596827	106.366304
46.1100006103516	1653.29626464844	1.53558573219925	0.382176280254498	0.00750370137393475	106.701928
46.310001373291	1659.06433105469	1.54204748105258	0.383714563213289	0.00754118105396628	107.074192
46.5099983215332	1663.60046386719	1.54873996507376	0.385066960006952	0.00757386907935143	107.366952
46.7099990844727	1669.68481445313	1.55543244909495	0.386804109439254	0.00760735478252172	107.759632
46.9099998474121	1674.57592773438	1.56212493311614	0.387748412322253	0.00764596462249756	108.075296
47.1100006103516	1680.10778808594	1.56881753355265	0.38996443618089	0.00767462002113461	108.43232
47.310001373291	1685.32702636719	1.57527928240597	0.39188694790937	0.0076949754729867	108.76916
47.5099983215332	1690.55383300781	1.58197176642716	0.393177120713517	0.00772831775248051	109.106496
47.7099990844727	1695.71667480469	1.58866425044835	0.394943315768614	0.00775380386039615	109.439696
47.9099998474121	1701.37451171875	1.59535685088485	0.396396033465862	0.00778145715594292	109.804848
48.1100006103516	1707.02355957031	1.60204933490604	0.397894124034792	0.00782808940857649	110.169432
48.310001373291	1712.07495117188	1.60851108375937	0.399005104554817	0.00786220096051693	110.49544
48.5099983215332	1716.88439941406	1.61543430294842	0.402026198571548	0.00789390690624714	110.80584
48.7099990844727	1722.16271972656	1.62189605180174	0.402899371692911	0.00792556535452604	111.146496
48.9099998474121	1727.68627929688	1.62858853582293	0.404574762796983	0.00795319955796003	111.502984
49.1100006103516	1732.49829101563	1.63528113625944	0.405798928113654	0.00796678103506565	111.813544
49.310001373291	1737.49328613281	1.64174276869744	0.407761690439656	0.00800274033099413	112.135912
49.5099983215332	1743.16247558594	1.64866610430181	0.408828258514404	0.00805280636996031	112.5018
49.7099990844727	1748.14855957031	1.65512785315514	0.409941392717883	0.00807436089962721	112.823592
49.9099998474121	1753.3662109375	1.66182045359164	0.411965127568692	0.00811475142836571	113.160336
50.1100006103516	1758.69677734375	1.66851282119751	0.414117996115237	0.0081425542011857	113.504368
50.310001373291	1763.859375	1.67497457005084	0.415091897593811	0.00817541964352131	113.837552
50.5099983215332	1769.07861328125	1.68189790565521	0.416700670029968	0.00819952506572008	114.1744
50.7099990844727	1774.41442871094	1.68859038967639	0.418833078583702	0.00823033880442381	114.518768
50.9099998474121	1779.771484375	1.6952829901129	0.419982214225456	0.00826941803097725	114.864504
51.1100006103516	1785.2978515625	1.7017446225509	0.422038254328072	0.00830541830509901	115.221168
51.310001373291	1790.32385253906	1.70843722298741	0.42335654143244	0.00833244435489178	115.545544
51.5099983215332	1795.24987792969	1.7151297070086	0.424849451519549	0.0083684865385294	115.863464
51.7099990844727	1800.39636230469	1.72182230744511	0.426047277869657	0.0083989268168807	116.195608
51.9099998474121	1806.08068847656	1.72851467505097	0.428165425546467	0.00842640269547701	116.562472
52.1100006103516	1811.28942871094	1.73520715907216	0.429504347266629	0.00846046954393387	116.89864
52.310001373291	1816.74633789063	1.74189975950867	0.430872256401926	0.00850140582770109	117.250816
52.5099983215332	1821.21923828125	1.74859224352986	0.432897068094462	0.00851972214877605	117.539496
52.7099990844727	1826.568359375	1.75528484396636	0.434333778684959	0.00854820944368839	117.88472
52.9099998474121	1832.31518554688	1.76197732798755	0.436039728811011	0.00857908464968205	118.255616
53.1100006103516	1836.38073730469	1.76866981200874	0.43830624781549	0.00861562322825193	118.518
53.310001373291	1841.76831054688	1.77536241244525	0.439459894550964	0.00864437036216259	118.865712
53.5099983215332	1846.69970703125	1.78205478005111	0.441108510131016	0.00868055690079927	119.183976
53.7099990844727	1851.73498535156	1.7887472640723	0.442322372691706	0.0087036145851016	119.508952
53.9099998474121	1857.0087890625	1.79543986450881	0.443996221292764	0.00873573962599039	119.849312
54.1100006103516	1862.73791503906	1.80213234852999	0.445833458798006	0.00877058878540993	120.219064
54.310001373291	1867.28125	1.8088249489665	0.447104044724256	0.00880216713994741	120.512288
54.5099983215332	1872.56567382813	1.81528658140451	0.448403268819675	0.00884139165282249	120.853336
54.7099990844727	1877.69689941406	1.82197918184102	0.450683466624469	0.00887222867459059	121.184504
54.9099998474121	1882.65551757813	1.8286716658622	0.452254171250388	0.00889810640364885	121.504528
55.1100006103516	1887.90014648438	1.83536426629871	0.453438318800181	0.00892405677586794	121.843008
55.310001373291	1892.53479003906	1.84205663390458	0.45535815297626	0.00895689707249403	122.14212
55.5099983215332	1898.03759765625	1.8485183827579	0.456844922155142	0.00899381563067436	122.497272
55.7099990844727	1903.50231933594	1.85544171836227	0.458648923086002	0.00902754068374634	122.849952
55.9099998474121	1908.33264160156	1.86213420238346	0.459529197541997	0.00905547570437193	123.161696
56.1100006103516	1913.36279296875	1.86882680281997	0.461382820503786	0.0090808654204011	123.486336
56.310001373291	1918.18774414063	1.87528843525797	0.463516073068604	0.00910614524036646	123.797736
56.5099983215332	1923.15405273438	1.88198103569448	0.464964134152979	0.00913665536791086	124.118256
56.7099990844727	1927.76928710938	1.88867351971567	0.466342578874901	0.00916935037821531	124.41612
56.9099998474121	1933.37084960938	1.89536600373685	0.468167389044538	0.00921294465661049	124.77764
57.1100006103516	1936.74877929688	1.90205848775804	0.468992482637987	0.00923098530620337	124.995648
57.310001373291	1941.77233886719	1.90852023661137	0.470222003059462	0.00925301294773817	125.319864
57.5099983215332	1946.10180664063	1.91521272063255	0.472254148917273	0.00929156597703695	125.59928
57.7099990844727	1951.11364746094	1.92190532106906	0.47303328756243	0.00931257288902998	125.922736
57.9099998474121	1956.49169921875	1.92859780509025	0.475467153592035	0.00935180857777596	126.269832
58.1100006103516	1961.4794921875	1.93529028911144	0.476568035082892	0.00938493199646473	126.591736
58.310001373291	1966.70153808594	1.94198288954794	0.478413363453001	0.0094243586063385	126.92876
58.5099983215332	1971.57861328125	1.94867537356913	0.479907786939293	0.00945683103054762	127.243528
58.7099990844727	1976.5166015625	1.95536785759032	0.481865426991135	0.00947222393006086	127.562216
58.9099998474121	1981.92504882813	1.9620603416115	0.483128533232957	0.00951631739735603	127.911272
59.1100006103516	1987.048828125	1.96875282563269	0.484994408907369	0.00954094342887402	128.241952
59.310001373291	1991.94689941406	1.97544530965388	0.487180222989991	0.00957232806831598	128.558072
59.5099983215332	1997.13659667969	1.98213802650571	0.487906509079039	0.00960626825690269	128.893008
59.7099990844727	2002.23205566406	1.9888305105269	0.489874510094523	0.00964058935642242	129.221864
59.9099998474121	2007.30200195313	1.99552299454808	0.49133988795802	0.00967476703226566	129.549072
60.1100006103516	2012.50939941406	2.00221547856927	0.493019528221339	0.00970327854156494	129.885152
60.310001373291	2017.423828125	2.00890796259046	0.494348991196603	0.00973091367632151	130.202328
60.5099983215332	2022.75415039063	2.01560044661164	0.495999644044787	0.00976300798356533	130.546336
60.7099990844727	2027.49047851563	2.02206219546497	0.497692846693099	0.00979213230311871	130.852016
60.9099998474121	2032.64074707031	2.02875467948616	0.499185698572546	0.00981846917420626	131.184408
61.1100006103516	2038.17895507813	2.03544739633799	0.50074071623385	0.00985220167785883	131.54184
61.310001373291	2043.08386230469	2.04213988035917	0.502478971611708	0.00987492688000202	131.858392
61.5099983215332	2048.27368164063	2.04883213154972	0.503580609802157	0.00991823058575392	132.193344
61.7099990844727	2053.19287109375	2.05552484840155	0.505527888890356	0.00994215998798609	132.510816
61.9099998474121	2058.22534179688	2.06221733242273	0.506556476466358	0.00998110882937908	132.835608
62.1100006103516	2062.85791015625	2.06890981644392	0.508741708472371	0.0100029911845922	133.134592
62.310001373291	2067.6806640625	2.07560230046511	0.510293990373611	0.0100365784019232	133.445848
62.5099983215332	2072.97143554688	2.08229501731694	0.512044643983245	0.0100609734654427	133.787304
62.7099990844727	2078.15600585938	2.08898726850748	0.512834580149502	0.0100945150479674	134.121912
62.9099998474121	2082.29541015625	2.09544925019145	0.51488121971488	0.010126150213182	134.389072
63.1100006103516	2087.75317382813	2.1023724693805	0.516484666150063	0.0101643092930317	134.741296
63.310001373291	2092.61474609375	2.10883398540318	0.518602028023452	0.0101993652060628	135.055072
63.5099983215332	2097.91455078125	2.11552670225501	0.519171066116542	0.0102259619161487	135.397104
63.7099990844727	2102.56298828125	2.1222191862762	0.520705129019916	0.0102540496736765	135.69712
63.9099998474121	2107.36669921875	2.12868093512952	0.522298796568066	0.01029057148844	136.007136
64.1100006103516	2111.96655273438	2.13560415431857	0.524024129845202	0.0103203589096665	136.304016
64.3099975585938	2116.9453125	2.1420659031719	0.525775016285479	0.0103481281548738	136.625328
64.5100021362305	2120.97924804688	2.14875838719308	0.527499883901328	0.0103690288960934	136.88568
64.7099990844727	2126.33056640625	2.15545087121427	0.52830867934972	0.010406943038106	137.23104
64.9100036621094	2130.56494140625	2.16214335523546	0.529984128661454	0.0104303695261478	137.504336
65.1100006103516	2135.591796875	2.16883583925664	0.532045611180365	0.0104663856327534	137.828752
65.3099975585938	2140.67358398438	2.17552855610847	0.533316750079393	0.0104927411302924	138.156736
65.5100021362305	2145.21826171875	2.18222104012966	0.5350784631446	0.0105196004733443	138.450032
65.7099990844727	2150.10913085938	2.18868278898299	0.536467880010605	0.0105564408004284	138.765696
65.9100036621094	2154.90356445313	2.19560600817204	0.538458290975541	0.0105967307463288	139.07512
66.1100006103516	2160.0341796875	2.20206775702536	0.540097593329847	0.0106195686385036	139.40624
66.3099975585938	2164.63842773438	2.20876024104655	0.541399349458516	0.0106530776247382	139.703392
66.5100021362305	2169.72729492188	2.21545272506773	0.542827299796045	0.010691081173718	140.031824
66.7099990844727	2174.52587890625	2.22214520908892	0.544476904906332	0.0107043627649546	140.34152
66.9100036621094	2179.30419921875	2.22883769311011	0.546299270354211	0.0107510145753622	140.649904
67.1100006103516	2184.04663085938	2.23553040996194	0.547371397260576	0.0107771633192897	140.955984
67.3099975585938	2188.90869140625	2.24222289398313	0.548796262592077	0.0108060836791992	141.269776
67.5100021362305	2193.65966796875	2.24891537800431	0.550612923689187	0.0108351968228817	141.5764
67.7099990844727	2198.84838867188	2.2556078620255	0.552269513718784	0.0108574386686087	141.911264
67.9100036621094	2202.95239257813	2.26230057887733	0.553839083295316	0.0109024131670594	142.176128
68.1100006103516	2207.93017578125	2.26899283006787	0.555528444238007	0.0109197804704309	142.497392
68.3099975585938	2212.68676757813	2.27568531408906	0.557479506824166	0.010966120287776	142.804384
68.5100021362305	2217.869140625	2.28237803094089	0.558591040316969	0.0109935449436307	143.138848
68.7099990844727	2222.271484375	2.28907028213143	0.560301647055894	0.0110255815088749	143.422976
68.9100036621094	2227.25610351563	2.29576299898326	0.56176824728027	0.0110604586079717	143.744672
69.1100006103516	2232.49780273438	2.30245548300445	0.562433851882815	0.011078642681241	144.08296
69.3099975585938	2236.67236328125	2.30891723185778	0.565297494176775	0.0111183300614357	144.352384
69.5100021362305	2241.84130859375	2.31560971587896	0.566242379136384	0.0111424066126347	144.685984
69.7099990844727	2247.06884765625	2.32230243273079	0.568267423659563	0.0111853117123246	145.02336
69.9100036621094	2251.5	2.32899468392134	0.569753290619701	0.0112035162746906	145.309344
70.1100006103516	2256.61791992188	2.33568716794252	0.571128271985799	0.0112405735999346	145.639648
70.3099975585938	2261.2734375	2.34237988479435	0.573054538108408	0.0112745342776179	145.940112
70.5100021362305	2266.37744140625	2.34884140081704	0.574316014535725	0.0113021414726973	146.26952
70.7099990844727	2271.01293945313	2.35553411766887	0.576202350202948	0.0113345971331	146.568688
70.9100036621094	2276.03735351563	2.36222660169005	0.577557133510709	0.0113688902929425	146.89296
71.1100006103516	2280.60888671875	2.36891908571124	0.578944862354547	0.0114003252238035	147.188
71.3099975585938	2285.52563476563	2.37561156973243	0.580156513024122	0.0114244157448411	147.505328
71.5100021362305	2290.59545898438	2.38207331858575	0.581563159357756	0.0114487502723932	147.832528
71.7099990844727	2294.80200195313	2.38876580260694	0.583658867981285	0.0114871356636286	148.104016
71.9100036621094	2299.7734375	2.39545828662813	0.585326110012829	0.0115219866856933	148.424864
72.1100006103516	2305.27807617188	2.40215077064931	0.586593523621559	0.0115467812865973	148.780128
72.3099975585938	2309.71850585938	2.4088432546705	0.588329392485321	0.0115623883903027	149.066704
72.5100021362305	2314.2900390625	2.41553597152233	0.589539820794016	0.0116013968363404	149.361744
72.7099990844727	2319.5400390625	2.42222822271287	0.591733201872557	0.0116411680355668	149.700576
72.9100036621094	2324.15698242188	2.42869020439684	0.592801079619676	0.0116663482040167	149.998544
73.1100006103516	2328.677734375	2.43561342358589	0.594728509895504	0.0116915870457888	150.290304
73.3099975585938	2333.990234375	2.44207517243922	0.595951336435974	0.0117292050272226	150.633168
73.5100021362305	2338.64672851563	2.4487676564604	0.597645528614521	0.0117701375856996	150.933696
73.7099990844727	2343.10815429688	2.45546014048159	0.599376624450088	0.0117755560204387	151.221632
73.9100036621094	2348.12280273438	2.46215262450278	0.600290135480464	0.011817998252809	151.54528
74.1100006103516	2352.85498046875	2.46884510852396	0.601951091084629	0.0118481125682592	151.850688
74.3099975585938	2357.46411132813	2.4755378253758	0.603733817115426	0.0118836462497711	152.14816
74.5100021362305	2362.23950195313	2.48223007656634	0.605266657657921	0.0119151109829545	152.456352
74.7099990844727	2366.9453125	2.48892279341817	0.606940768193454	0.0119387581944466	152.760064
74.9100036621094	2371.720703125	2.49561527743936	0.608068890869617	0.0119751030579209	153.068256
75.1100006103516	2376.69995117188	2.50207702629268	0.609582522884011	0.0120001910254359	153.389616
75.3099975585938	2381.59936523438	2.50876951031387	0.612194184213877	0.0120464432984591	153.705808
75.5100021362305	2386.251953125	2.51546199433506	0.613137963227928	0.0120636718347669	154.006096
75.7099990844727	2390.52783203125	2.52215447835624	0.614295771811157	0.0120931705459952	154.282048
75.9100036621094	2395.66625976563	2.52884696237743	0.616405333857983	0.0121263852342963	154.61368
76.1100006103516	2399.98388671875	2.53553967922926	0.618060119450092	0.012149971909821	154.892336
76.3099975585938	2405.25244140625	2.5422319304198	0.618185207713395	0.0121821518987417	155.232352
76.5100021362305	2409.20361328125	2.54869391210377	0.620927079580724	0.0122073069214821	155.48736
76.7099990844727	2414.46484375	2.55561713129282	0.622470921371132	0.0122409015893936	155.826912
76.9100036621094	2418.875	2.5620786473155	0.62391982646659	0.0122715849429369	156.111536
77.1100006103516	2423.71118164063	2.56877136416733	0.625896034762263	0.0123104639351368	156.423664
77.3099975585938	2428.90502929688	2.57546384818852	0.6268490687944	0.0123462937772274	156.758864
77.5100021362305	2433	2.58215633220971	0.628936861176044	0.0123792942613363	157.023152
77.7099990844727	2438.05322265625	2.58884881623089	0.630733440630138	0.0124095994979143	157.34928
77.9100036621094	2442.68383789063	2.59531079791486	0.632021343335509	0.0124353002756834	157.648144
78.1100006103516	2448.02954101563	2.60200304910541	0.633457500953227	0.0124593507498503	157.993152
78.3099975585938	2452.2353515625	2.60869576595724	0.634805939625949	0.0124992858618498	158.264592
78.5100021362305	2456.94311523438	2.61538824997842	0.636352633591741	0.0125216506421566	158.568416
78.7099990844727	2461.62255859375	2.62208050116897	0.637843739241362	0.0125552341341972	158.870432
78.9100036621094	2466.22534179688	2.62854248285294	0.640139856841415	0.0125960949808359	159.167488
79.1100006103516	2470.8671875	2.63523473404348	0.641037127934396	0.0126128671690822	159.467056
79.3099975585938	2475.60766601563	2.64192745089531	0.643274281173944	0.0126461805775762	159.773008
79.5100021362305	2480.21704101563	2.6486199349165	0.644250540062785	0.0126675525680184	160.070496
79.7099990844727	2484.3642578125	2.65508168376982	0.645504158455879	0.0126953953877091	160.338144
79.9100036621094	2488.84692382813	2.66177416779101	0.647169363219291	0.0127378525212407	160.627456
80.1100006103516	2493.95556640625	2.66846688464284	0.648688292130828	0.0127663668245077	160.957168
80.3099975585938	2499.14184570313	2.67515913583338	0.649850233457983	0.0128028439357877	161.291872
80.5100021362305	2503.54467773438	2.68185185268521	0.6517005385831	0.0128272501751781	161.576032
80.7099990844727	2507.99340820313	2.6885443367064	0.652916962280869	0.0128499669954181	161.863152
80.9100036621094	2512.83081054688	2.69500585272908	0.654831295832992	0.0128956567496061	162.175344
81.1100006103516	2517.75561523438	2.70169856958091	0.65638410160318	0.0129163423553109	162.493184
81.3099975585938	2521.92211914063	2.70862178876996	0.657260301522911	0.0129387928172946	162.762096
81.5100021362305	2526.37524414063	2.71531427279115	0.659896992146969	0.012976823374629	163.049488
81.7099990844727	2531.15991210938	2.72177602164447	0.661247642710805	0.0130157461389899	163.358288
81.9100036621094	2535.33837890625	2.7284687384963	0.662432517856359	0.0130430096760392	163.627968
82.1100006103516	2540.330078125	2.73516098968685	0.664203951600939	0.0130558796226978	163.950128
82.3099975585938	2544.556640625	2.74185370653868	0.665686966385692	0.0130887860432267	164.222896
82.5100021362305	2549.03149414063	2.74854619055986	0.666802516207099	0.0131212286651134	164.511696
82.7099990844727	2553.70043945313	2.75523844175041	0.669183093123138	0.0131552489474416	164.813024
82.9100036621094	2558.32348632813	2.76193115860224	0.670066277962178	0.0131903262808919	165.111392
83.1100006103516	2562.62524414063	2.76862364262342	0.671476882416755	0.0132291754707694	165.389024
83.3099975585938	2566.80029296875	2.77531612664461	0.673047499731183	0.0132454074919224	165.65848
83.5100021362305	2571.91186523438	2.78177787549794	0.674729410093278	0.0132739087566733	165.988368
83.7099990844727	2576.6923828125	2.78870132751763	0.675947230774909	0.0133029278367758	166.296912
83.9100036621094	2580.58764648438	2.79516284354031	0.677887292113155	0.0133343786001205	166.548304
84.120002746582	10.9679269790649	2.80231679789722	0.63000142108649	0.0126571599394083	0.707858